Traceback (most recent call last):
  File "/home/gslee/anaconda3/lib/python3.9/site-packages/jupyter_cache/executors/utils.py", line 51, in single_nb_execution
    executenb(
  File "/home/gslee/anaconda3/lib/python3.9/site-packages/nbclient/client.py", line 1112, in execute
    return NotebookClient(nb=nb, resources=resources, km=km, **kwargs).execute()
  File "/home/gslee/anaconda3/lib/python3.9/site-packages/nbclient/util.py", line 74, in wrapped
    return just_run(coro(*args, **kwargs))
  File "/home/gslee/anaconda3/lib/python3.9/site-packages/nbclient/util.py", line 53, in just_run
    return loop.run_until_complete(coro)
  File "/home/gslee/anaconda3/lib/python3.9/asyncio/base_events.py", line 642, in run_until_complete
    return future.result()
  File "/home/gslee/anaconda3/lib/python3.9/site-packages/nbclient/client.py", line 553, in async_execute
    await self.async_execute_cell(
  File "/home/gslee/anaconda3/lib/python3.9/site-packages/nbclient/client.py", line 857, in async_execute_cell
    self._check_raise_for_error(cell, exec_reply)
  File "/home/gslee/anaconda3/lib/python3.9/site-packages/nbclient/client.py", line 760, in _check_raise_for_error
    raise CellExecutionError.from_cell_and_msg(cell, exec_reply_content)
nbclient.exceptions.CellExecutionError: An error occurred while executing the following cell:
------------------
k = 4
num_val_samples = len(train_data) // k

num_epochs = 500
all_mae_histories = []   # 모든 에포크에 대한 평균절대오차 저장

for i in range(k):       # 교차 검증
    
    print(f"{i+1}번 째 폴드(fold) 훈련 시작")

    val_data = train_data[i * num_val_samples: (i + 1) * num_val_samples]
    val_targets = train_targets[i * num_val_samples: (i + 1) * num_val_samples]

    partial_train_data = np.concatenate(
        [train_data[:i * num_val_samples],
         train_data[(i + 1) * num_val_samples:]],
        axis=0)
    partial_train_targets = np.concatenate(
        [train_targets[:i * num_val_samples],
         train_targets[(i + 1) * num_val_samples:]],
        axis=0)
    
    model = build_model()    # 유닛 수: 64
    history = model.fit(partial_train_data, partial_train_targets,
                        validation_data=(val_data, val_targets),
                        epochs=num_epochs, batch_size=16, verbose=0)
    
    mae_history = history.history["val_mae"]
    all_mae_histories.append(mae_history)
------------------

[0;31m---------------------------------------------------------------------------[0m
[0;31mNameError[0m                                 Traceback (most recent call last)
[0;32m/tmp/ipykernel_1334/4201190624.py[0m in [0;36m<module>[0;34m[0m
[1;32m      1[0m [0mk[0m [0;34m=[0m [0;36m4[0m[0;34m[0m[0;34m[0m[0m
[0;32m----> 2[0;31m [0mnum_val_samples[0m [0;34m=[0m [0mlen[0m[0;34m([0m[0mtrain_data[0m[0;34m)[0m [0;34m//[0m [0mk[0m[0;34m[0m[0;34m[0m[0m
[0m[1;32m      3[0m [0;34m[0m[0m
[1;32m      4[0m [0mnum_epochs[0m [0;34m=[0m [0;36m500[0m[0;34m[0m[0;34m[0m[0m
[1;32m      5[0m [0mall_mae_histories[0m [0;34m=[0m [0;34m[[0m[0;34m][0m   [0;31m# 모든 에포크에 대한 평균절대오차 저장[0m[0;34m[0m[0;34m[0m[0m

[0;31mNameError[0m: name 'train_data' is not defined
NameError: name 'train_data' is not defined

