Traceback (most recent call last):
  File "/home/gslee/anaconda3/lib/python3.9/site-packages/jupyter_cache/executors/utils.py", line 51, in single_nb_execution
    executenb(
  File "/home/gslee/anaconda3/lib/python3.9/site-packages/nbclient/client.py", line 1112, in execute
    return NotebookClient(nb=nb, resources=resources, km=km, **kwargs).execute()
  File "/home/gslee/anaconda3/lib/python3.9/site-packages/nbclient/util.py", line 74, in wrapped
    return just_run(coro(*args, **kwargs))
  File "/home/gslee/anaconda3/lib/python3.9/site-packages/nbclient/util.py", line 53, in just_run
    return loop.run_until_complete(coro)
  File "/home/gslee/anaconda3/lib/python3.9/asyncio/base_events.py", line 642, in run_until_complete
    return future.result()
  File "/home/gslee/anaconda3/lib/python3.9/site-packages/nbclient/client.py", line 553, in async_execute
    await self.async_execute_cell(
  File "/home/gslee/anaconda3/lib/python3.9/site-packages/nbclient/client.py", line 857, in async_execute_cell
    self._check_raise_for_error(cell, exec_reply)
  File "/home/gslee/anaconda3/lib/python3.9/site-packages/nbclient/client.py", line 760, in _check_raise_for_error
    raise CellExecutionError.from_cell_and_msg(cell, exec_reply_content)
nbclient.exceptions.CellExecutionError: An error occurred while executing the following cell:
------------------
from tensorflow.keras.datasets import mnist
import numpy as np

# MNIST Îç∞Ïù¥ÌÑ∞ÏÖã Ï†ÅÏû¨ Î∞è Ï†ÑÏ≤òÎ¶¨
(train_images, train_labels), _ = mnist.load_data()

train_images = train_images.reshape((60000, 28 * 28))
train_images = train_images.astype("float32") / 255

# Î∞±ÏÉâ ÏÜåÏùå Ï∂îÍ∞Ä
train_images_with_noise_channels = np.concatenate(
    [train_images, np.random.random((len(train_images), 784))], axis=1)

# ÌÅ¨Í∏∞Î•º ÎßûÏ∂îÍ∏∞ ÏúÑÌï¥ ÏòÅ ÌñâÎ†¨ Ï∂îÍ∞Ä
train_images_with_zeros_channels = np.concatenate(
    [train_images, np.zeros((len(train_images), 784))], axis=1)
------------------

[0;31m---------------------------------------------------------------------------[0m
[0;31mModuleNotFoundError[0m                       Traceback (most recent call last)
[0;32m/tmp/ipykernel_828/4133405677.py[0m in [0;36m<module>[0;34m[0m
[0;32m----> 1[0;31m [0;32mfrom[0m [0mtensorflow[0m[0;34m.[0m[0mkeras[0m[0;34m.[0m[0mdatasets[0m [0;32mimport[0m [0mmnist[0m[0;34m[0m[0;34m[0m[0m
[0m[1;32m      2[0m [0;32mimport[0m [0mnumpy[0m [0;32mas[0m [0mnp[0m[0;34m[0m[0;34m[0m[0m
[1;32m      3[0m [0;34m[0m[0m
[1;32m      4[0m [0;31m# MNIST Îç∞Ïù¥ÌÑ∞ÏÖã Ï†ÅÏû¨ Î∞è Ï†ÑÏ≤òÎ¶¨[0m[0;34m[0m[0;34m[0m[0m
[1;32m      5[0m [0;34m([0m[0mtrain_images[0m[0;34m,[0m [0mtrain_labels[0m[0;34m)[0m[0;34m,[0m [0m_[0m [0;34m=[0m [0mmnist[0m[0;34m.[0m[0mload_data[0m[0;34m([0m[0;34m)[0m[0;34m[0m[0;34m[0m[0m

[0;31mModuleNotFoundError[0m: No module named 'tensorflow'
ModuleNotFoundError: No module named 'tensorflow'

